Traceback (most recent call last):
  File "C:\Users\visha\Documents\SwasthyaSetu-main\ai\symptom-checker\run.py", line 277, in <module>
    success = main()
  File "C:\Users\visha\Documents\SwasthyaSetu-main\ai\symptom-checker\run.py", line 209, in main
    print("\U0001f3e5 Medical Symptom Checker - Application Setup")
    ~~~~~^^^^^^^^^^^^^^^^^^^^^^^^^^^^^^^^^^^^^^^^^^^^^^^^^^
  File "C:\Users\visha\AppData\Local\Programs\Python\Python313\Lib\encodings\cp1252.py", line 19, in encode
    return codecs.charmap_encode(input,self.errors,encoding_table)[0]
           ~~~~~~~~~~~~~~~~~~~~~^^^^^^^^^^^^^^^^^^^^^^^^^^^^^^^^^^
UnicodeEncodeError: 'charmap' codec can't encode character '\U0001f3e5' in position 0: character maps to <undefined>

During handling of the above exception, another exception occurred:

Traceback (most recent call last):
  File "C:\Users\visha\Documents\SwasthyaSetu-main\ai\symptom-checker\run.py", line 282, in <module>
    print(f"\n\u274c Unexpected error: {str(e)}")
    ~~~~~^^^^^^^^^^^^^^^^^^^^^^^^^^^^^^^^^^^^
  File "C:\Users\visha\AppData\Local\Programs\Python\Python313\Lib\encodings\cp1252.py", line 19, in encode
    return codecs.charmap_encode(input,self.errors,encoding_table)[0]
           ~~~~~~~~~~~~~~~~~~~~~^^^^^^^^^^^^^^^^^^^^^^^^^^^^^^^^^^
UnicodeEncodeError: 'charmap' codec can't encode character '\u274c' in position 2: character maps to <undefined>
